Workbook
Name Срез_Shoe_model: #N/A

Sheet График 1
A3: Названия строк | B3: Сумма по полю sales
A4: 2022 | B4: 573
A5: янв | B5: 38
A6: февр | B6: 22
A7: март | B7: 48
A8: апр | B8: 31
A9: май | B9: 47
A10: июнь | B10: 66
A11: июль | B11: 73
A12: авг | B12: 69
A13: сент | B13: 60
A14: окт | B14: 33
A15: нояб | B15: 50
... A43: Общий итог | B43: 1793

Sheet Лист2
A3: Названия строк | B3: Среднее по полю sales
A4: 2022
A5: янв | B5: 12.666667
A6: февр | B6: 11
A7: март | B7: 16
A8: апр | B8: 15.5
A9: май | B9: 15.666667
A10: июнь | B10: 22
A11: июль | B11: 24.333333
A12: авг | B12: 23
A13: сент | B13: 20
A14: окт | B14: 16.5
A15: нояб | B15: 16.666667
A16: дек | B16: 18
A17: 2023
A18: янв | B18: 15.666667
A19: февр | B19: 10.5
A20: март | B20: 17.333333
A21: апр | B21: 17
A22: май | B22: 17.666667
A23: июнь | B23: 22
A24: июль | B24: 26
A25: авг | B25: 24
A26: сент | B26: 19.666667
A27: окт | B27: 17
A28: нояб | B28: 18.666667
A29: дек | B29: 18
A30: 2024
A31: янв | B31: 16.333333
A32: февр | B32: 11.5
A33: март | B33: 17.666667
A34: апр | B34: 16.5
A35: май | B35: 16.666667
A36: июнь | B36: 22.333333
A37: июль | B37: 25.333333
A38: авг | B38: 24
A39: сент | B39: 19.666667
A40: окт | B40: 18
A41: нояб | B41: 18
A42: дек | B42: 20
...

Sheet Лист3
A3: Названия строк | B3: Среднее по полю sales
A4: янв | B4: 14.888889
A5: февр | B5: 11
A6: март | B6: 17
A7: апр | B7: 16.333333
A8: май | B8: 16.666667
A9: июнь | B9: 22.111111
A10: июль | B10: 25.222222
A11: авг | B11: 23.666667
A12: сент | B12: 19.777778
A13: окт | B13: 17.166667
A14: нояб | B14: 17.777778
A15: дек | B15: 18.666667
A16: Общий итог | B16: 18.677083

Sheet Лист4
A3: Названия строк | B3: Сумма по полю sales
A4: 2022 | B4: 573
A5: 2023 | B5: 608
A6: 2024 | B6: 612
A7: Общий итог | B7: 1793

Sheet факт
A3: Названия строк | B3: Сумма по полю sales
A4: 2022
A5: янв | B5: 38
A6: февр | B6: 22
A7: март | B7: 48
A8: апр | B8: 31
A9: май | B9: 47
A10: июнь | B10: 66
A11: июль | B11: 73
A12: авг | B12: 69
A13: сент | B13: 60
A14: окт | B14: 33
A15: нояб | B15: 50
A16: дек | B16: 36
A17: 2023
A18: янв | B18: 47
A19: февр | B19: 21
A20: март | B20: 52
A21: апр | B21: 34
A22: май | B22: 53
A23: июнь | B23: 66
A24: июль | B24: 78
A25: авг | B25: 72
A26: сент | B26: 59
A27: окт | B27: 34
A28: нояб | B28: 56
A29: дек | B29: 36
A30: 2024
A31: янв | B31: 49
A32: февр | B32: 23
A33: март | B33: 53
A34: апр | B34: 33
A35: май | B35: 50
A36: июнь | B36: 67
A37: июль | B37: 76
A38: авг | B38: 72
A39: сент | B39: 59
A40: окт | B40: 36
A41: нояб | B41: 54
A42: дек | B42: 40
...

Sheet Лист10
A3: Количество по полю sales | B3: Названия столбцов
A4: Названия строк | B4: 2022 | C4: 2023 | D4: 2024 | E4: Общий итог
A5: янв | B5: 15 | C5: 18 | D5: 18 | E5: 51 | F5: =AVERAGE(B5:D5) -> 17
A6: февр | B6: 10 | C6: 10 | D6: 10 | E6: 30 | F6: =AVERAGE(B6:D6) -> 10
A7: март | B7: 11 | C7: 11 | D7: 11 | E7: 33 | F7: =AVERAGE(B7:D7) -> 11
A8: апр | B8: 13 | C8: 13 | D8: 13 | E8: 39 | F8: =AVERAGE(B8:D8) -> 13
A9: май | B9: 11 | C9: 11 | D9: 11 | E9: 33 | F9: =AVERAGE(B9:D9) -> 11
A10: июнь | B10: 13 | C10: 13 | D10: 13 | E10: 39 | F10: =AVERAGE(B10:D10) -> 13
A11: июль | B11: 13 | C11: 13 | D11: 13 | E11: 39 | F11: =AVERAGE(B11:D11) -> 13
A12: авг | B12: 12 | C12: 12 | D12: 12 | E12: 36 | F12: =AVERAGE(B12:D12) -> 12
A13: сент | B13: 12 | C13: 12 | D13: 12 | E13: 36 | F13: =AVERAGE(B13:D13) -> 12
A14: окт | B14: 13 | C14: 13 | D14: 13 | E14: 39 | F14: =AVERAGE(B14:D14) -> 13
A15: нояб | B15: 11 | C15: 11 | D15: 11 | E15: 33 | F15: =AVERAGE(B15:D15) -> 11
A16: дек | B16: 13 | C16: 13 | D16: 13 | E16: 39 | F16: =AVERAGE(B16:D16) -> 13
A17: Общий итог | B17: 147 | C17: 150 | D17: 150 | E17: 447

Sheet Данные
A1: Shoe_model | B1: Shoe _Type | C1: Gender | D1: Cost | E1: Column2 | F1: month | G1: year | H1: sales | I1: revenue | J1: stock | K1: price | L1: Date
A2: Doe Runner | B2: Running | C2: F | D2: 28 | E2: Istanbul | F2: 1 | G2: 2022 | H2: 7 | I2: 310 | J2: 20 | K2: 31 | L2: =DATE(sales__2[[#This Row],[year]],sales__2[[#This Row],[month]],1) -> 44562
A3: Doe Trek | B3: Hiking | C3: F | D3: 32 | E3: Istanbul | F3: 1 | G3: 2022 | H3: 8 | I3: 272 | J3: 18 | K3: 34 | L3: =DATE(sales__2[[#This Row],[year]],sales__2[[#This Row],[month]],1) -> 44562 | Q3: Названия строк | R3: Среднее по полю sales | S3: Названия строк | T3: Сумма по полю sales | V3: Названия строк | W3: Среднее по полю sales | X3: КС | Y3: КС | Z3: Сравнение
A4: Doe Canvas | B4: Casual | C4: F | D4: 18 | E4: Istanbul | F4: 1 | G4: 2022 | H4: 12 | I4: 247 | J4: 25 | K4: 19 | L4: =DATE(sales__2[[#This Row],[year]],sales__2[[#This Row],[month]],1) -> 44562 | Q4: 2022 | R4: 17.90625 | S4: 2022 | T4: 573 | V4: янв | W4: 14.888889 | X4: =W4/R$7 -> 0.7971742 | Y4: ='Сводная '!G5 -> 0.7971742 | Z4: =X4-Y4 -> 0
A5: Doe Vintage | B5: Limited | C5: F | D5: 45 | E5: Istanbul | F5: 1 | G5: 2022 | H5: 3 | I5: 144 | J5: 8 | K5: 48 | L5: =DATE(sales__2[[#This Row],[year]],sales__2[[#This Row],[month]],1) -> 44562 | Q5: 2023 | R5: 19 | S5: 2023 | T5: 608 | V5: февр | W5: 11 | X5: =W5/R$7 -> 0.58895706 | Y5: ='Сводная '!G6 -> 0.58895706 | Z5: =X5-Y5 -> 0
A6: Doe Slip-On | B6: Casual | C6: F | D6: 15 | E6: Istanbul | F6: 1 | G6: 2022 | H6: 18 | I6: 288 | J6: 35 | K6: 16 | L6: =DATE(sales__2[[#This Row],[year]],sales__2[[#This Row],[month]],1) -> 44562 | Q6: 2024 | R6: 19.125 | S6: 2024 | T6: 612 | V6: март | W6: 17 | X6: =W6/R$7 -> 0.91020636 | Y6: ='Сводная '!G7 -> 0.91020636 | Z6: =X6-Y6 -> 0
A7: Doe Runner | B7: Running | C7: F | D7: 28 | E7: Ankara | F7: 1 | G7: 2022 | H7: 7 | I7: 217 | J7: 15 | K7: 31 | L7: =DATE(sales__2[[#This Row],[year]],sales__2[[#This Row],[month]],1) -> 44562 | Q7: Общий итог | R7: 18.677083 | S7: Общий итог | T7: 1793 | V7: апр | W7: 16.333333 | X7: =W7/R$7 -> 0.87451199 | Y7: ='Сводная '!G8 -> 0.87451199 | Z7: =X7-Y7 -> 0
A8: Doe Runner | B8: Running | C8: F | D8: 28 | E8: Izmir | F8: 1 | G8: 2022 | H8: 8 | I8: 248 | J8: 18 | K8: 31 | L8: =DATE(sales__2[[#This Row],[year]],sales__2[[#This Row],[month]],1) -> 44562 | V8: май | W8: 16.666667 | X8: =W8/R$7 -> 0.89235917 | Y8: ='Сводная '!G9 -> 0.89235917 | Z8: =X8-Y8 -> 0
A9: Doe Canvas | B9: Casual | C9: F | D9: 18 | E9: Izmir | F9: 1 | G9: 2022 | H9: 15 | I9: 285 | J9: 30 | K9: 19 | L9: =DATE(sales__2[[#This Row],[year]],sales__2[[#This Row],[month]],1) -> 44562 | V9: июнь | W9: 22.111111 | X9: =W9/R$7 -> 1.1838632 | Y9: ='Сводная '!G10 -> 1.1838632 | Z9: =X9-Y9 -> 0
A10: Doe Slip-On | B10: Casual | C10: F | D10: 15 | E10: Izmir | F10: 1 | G10: 2022 | H10: 20 | I10: 320 | J10: 40 | K10: 16 | L10: =DATE(sales__2[[#This Row],[year]],sales__2[[#This Row],[month]],1) -> 44562 | V10: июль | W10: 25.222222 | X10: =W10/R$7 -> 1.3504369 | Y10: ='Сводная '!G11 -> 1.3504369 | Z10: =X10-Y10 -> 0
A11: Doe Runner | B11: Running | C11: F | D11: 30 | E11: Istanbul | F11: 1 | G11: 2022 | H11: 10 | I11: 320 | J11: 22 | K11: 32 | L11: =DATE(sales__2[[#This Row],[year]],sales__2[[#This Row],[month]],1) -> 44562 | V11: авг | W11: 23.666667 | X11: =W11/R$7 -> 1.26715 | Y11: ='Сводная '!G12 -> 1.26715 | Z11: =X11-Y11 -> 0
A12: Doe Trek | B12: Hiking | C12: M | D12: 35 | E12: Istanbul | F12: 1 | G12: 2022 | H12: 6 | I12: 222 | J12: 15 | K12: 37 | L12: =DATE(sales__2[[#This Row],[year]],sales__2[[#This Row],[month]],1) -> 44562 | V12: сент | W12: 19.777778 | X12: =W12/R$7 -> 1.0589329 | Y12: ='Сводная '!G13 -> 1.0589329 | Z12: =X12-Y12 -> 0
A13: Doe Canvas | B13: Casual | C13: M | D13: 20 | E13: Istanbul | F13: 1 | G13: 2022 | H13: 11 | I13: 252 | J13: 25 | K13: 21 | L13: =DATE(sales__2[[#This Row],[year]],sales__2[[#This Row],[month]],1) -> 44562 | V13: окт | W13: 17.166667 | X13: =W13/R$7 -> 0.91912995 | Y13: ='Сводная '!G14 -> 0.91912995 | Z13: =X13-Y13 -> 0
A14: Doe Vintage | B14: Limited | C14: M | D14: 48 | E14: Istanbul | F14: 1 | G14: 2022 | H14: 2 | I14: 104 | J14: 6 | K14: 52 | L14: =DATE(sales__2[[#This Row],[year]],sales__2[[#This Row],[month]],1) -> 44562 | V14: нояб | W14: 17.777778 | X14: =W14/R$7 -> 0.95184979 | Y14: ='Сводная '!G15 -> 0.95184979 | Z14: =X14-Y14 -> 0
A15: Doe Slip-On | B15: Casual | C15: M | D15: 17 | E15: Istanbul | F15: 1 | G15: 2022 | H15: 15 | I15: 270 | J15: 30 | K15: 18 | L15: =DATE(sales__2[[#This Row],[year]],sales__2[[#This Row],[month]],1) -> 44562 | V15: дек | W15: 18.666667 | X15: =W15/R$7 -> 0.99944228 | Y15: ='Сводная '!G16 -> 0.99944228 | Z15: =X15-Y15 -> 0
A16: Doe Air | B16: Running | C16: M | D16: 33 | E16: Istanbul | F16: 1 | G16: 2022 | H16: 7 | I16: 252 | J16: 16 | K16: 36 | L16: =DATE(sales__2[[#This Row],[year]],sales__2[[#This Row],[month]],1) -> 44562 | V16: Общий итог | W16: 18.677083 | X16: =SUM(X4:X15) -> 11.794014 | Y16: ='Сводная '!G17 -> 11.794014
A17: Doe Runner | B17: Running | C17: F | D17: 28 | E17: Istanbul | F17: 2 | G17: 2022 | H17: 8 | I17: 248 | J17: 18 | K17: 31 | L17: =DATE(sales__2[[#This Row],[year]],sales__2[[#This Row],[month]],1) -> 44593
A18: Doe Runner | B18: Running | C18: F | D18: 28 | E18: Izmir | F18: 2 | G18: 2022 | H18: 7 | I18: 217 | J18: 15 | K18: 31 | L18: =DATE(sales__2[[#This Row],[year]],sales__2[[#This Row],[month]],1) -> 44593
A19: Doe Trek | B19: Hiking | C19: F | D19: 32 | E19: Istanbul | F19: 2 | G19: 2022 | H19: 6 | I19: 204 | J19: 15 | K19: 34 | L19: =DATE(sales__2[[#This Row],[year]],sales__2[[#This Row],[month]],1) -> 44593
A20: Doe Canvas | B20: Casual | C20: F | D20: 18 | E20: Istanbul | F20: 2 | G20: 2022 | H20: 12 | I20: 209 | J20: 22 | K20: 19 | L20: =DATE(sales__2[[#This Row],[year]],sales__2[[#This Row],[month]],1) -> 44593
A21: Doe Slip-On | B21: Casual | C21: F | D21: 15 | E21: Istanbul | F21: 2 | G21: 2022 | H21: 16 | I21: 256 | J21: 30 | K21: 16 | L21: =DATE(sales__2[[#This Row],[year]],sales__2[[#This Row],[month]],1) -> 44593
A22: Doe Runner | B22: Running | C22: F | D22: 30 | E22: Istanbul | F22: 2 | G22: 2022 | H22: 8 | I22: 256 | J22: 18 | K22: 32 | L22: =DATE(sales__2[[#This Row],[year]],sales__2[[#This Row],[month]],1) -> 44593
A23: Doe Trek | B23: Hiking | C23: M | D23: 35 | E23: Istanbul | F23: 2 | G23: 2022 | H23: 5 | I23: 185 | J23: 12 | K23: 37 | L23: =DATE(sales__2[[#This Row],[year]],sales__2[[#This Row],[month]],1) -> 44593
A24: Doe Canvas | B24: Casual | C24: M | D24: 20 | E24: Istanbul | F24: 2 | G24: 2022 | H24: 10 | I24: 210 | J24: 20 | K24: 21 | L24: =DATE(sales__2[[#This Row],[year]],sales__2[[#This Row],[month]],1) -> 44593
A25: Doe Slip-On | B25: Casual | C25: M | D25: 17 | E25: Istanbul | F25: 2 | G25: 2022 | H25: 13 | I25: 234 | J25: 25 | K25: 18 | L25: =DATE(sales__2[[#This Row],[year]],sales__2[[#This Row],[month]],1) -> 44593
A26: Doe Air | B26: Running | C26: M | D26: 33 | E26: Istanbul | F26: 2 | G26: 2022 | H26: 6 | I26: 216 | J26: 15 | K26: 36 | L26: =DATE(sales__2[[#This Row],[year]],sales__2[[#This Row],[month]],1) -> 44593
A27: Doe Runner | B27: Running | C27: F | D27: 28 | E27: Istanbul | F27: 3 | G27: 2022 | H27: 12 | I27: 372 | J27: 25 | K27: 31 | L27: =DATE(sales__2[[#This Row],[year]],sales__2[[#This Row],[month]],1) -> 44621
A28: Doe Runner | B28: Running | C28: F | D28: 28 | E28: Antalya | F28: 3 | G28: 2022 | H28: 8 | I28: 248 | J28: 18 | K28: 31 | L28: =DATE(sales__2[[#This Row],[year]],sales__2[[#This Row],[month]],1) -> 44621
... A222: Doe Canvas | B222: Casual | C222: M | D222: 20 | E222: Istanbul | F222: 6 | G222: 2023 | H222: 19 | I222: 418 | J222: 40 | K222: 22 | L222: =DATE(sales__2[[#This Row],[year]],sales__2[[#This Row],[month]],1) -> 45078
A223: Doe Slip-On | B223: Casual | C223: M | D223: 17 | E223: Istanbul | F223: 6 | G223: 2023 | H223: 23+H268 | I223: 437 | J223: 45 | K223: 19 | L223: =DATE(sales__2[[#This Row],[year]],sales__2[[#This Row],[month]],1) -> 45078
A224: Doe Air | B224: Running | C224: M | D224: 33 | E224: Istanbul | F224: 6 | G224: 2023 | H224: 12 | I224: 456 | J224: 25 | K224: 38 | L224: =DATE(sales__2[[#This Row],[year]],sales__2[[#This Row],[month]],1) -> 45078
A225: Doe Runner | B225: Running | C225: F | D225: 28 | E225: Istanbul | F225: 7 | G225: 2023 | H225: 20 | I225: 640 | J225: 45 | K225: 32 | L225: =DATE(sales__2[[#This Row],[year]],sales__2[[#This Row],[month]],1) -> 45108
A226: Doe Runner | B226: Running | C226: F | D226: 28 | E226: Antalya | F226: 7 | G226: 2023 | H226: 16 | I226: 512 | J226: 35 | K226: 32 | L226: =DATE(sales__2[[#This Row],[year]],sales__2[[#This Row],[month]],1) -> 45108
A227: Doe Trek | B227: Hiking | C227: F | D227: 32 | E227: Istanbul | F227: 7 | G227: 2023 | H227: 16 | I227: 504 | J227: 30 | K227: 36 | L227: =DATE(sales__2[[#This Row],[year]],sales__2[[#This Row],[month]],1) -> 45108
A228: Doe Canvas | B228: Casual | C228: F | D228: 18 | E228: Istanbul | F228: 7 | G228: 2023 | H228: 26 | I228: 500 | J228: 50 | K228: 20 | L228: =DATE(sales__2[[#This Row],[year]],sales__2[[#This Row],[month]],1) -> 45108
A229: Doe Canvas | B229: Casual | C229: F | D229: 18 | E229: Izmir | F229: 7 | G229: 2023 | H229: 30 | I229: 560 | J229: 55 | K229: 20 | L229: =DATE(sales__2[[#This Row],[year]],sales__2[[#This Row],[month]],1) -> 45108
A230: Doe Slip-On | B230: Casual | C230: F | D230: 15 | E230: Istanbul | F230: 7 | G230: 2023 | H230: 30 | I230: 510 | J230: 60 | K230: 17 | L230: =DATE(sales__2[[#This Row],[year]],sales__2[[#This Row],[month]],1) -> 45108
A231: Doe Slip-On | B231: Casual | C231: F | D231: 15 | E231: Izmir | F231: 7 | G231: 2023 | H231: 28 | I231: 476 | J231: 55 | K231: 17 | L231: =DATE(sales__2[[#This Row],[year]],sales__2[[#This Row],[month]],1) -> 45108
A232: Doe Slip-On | B232: Casual | C232: F | D232: 15 | E232: Antalya | F232: 7 | G232: 2023 | H232: 25 | I232: 425 | J232: 50 | K232: 17 | L232: =DATE(sales__2[[#This Row],[year]],sales__2[[#This Row],[month]],1) -> 45108
A233: Doe Runner | B233: Running | C233: F | D233: 30 | E233: Istanbul | F233: 7 | G233: 2023 | H233: 19 | I233: 627 | J233: 40 | K233: 33 | L233: =DATE(sales__2[[#This Row],[year]],sales__2[[#This Row],[month]],1) -> 45108
...

Sheet Лист5
A1: Date | B1: sales | C1: Прогноз(sales) | D1: Привязка низкой вероятности(sales) | E1: Привязка высокой вероятности(sales) | G1: Статистика | H1: Значение
A2: 44562 | B2: 9.9333333 | G2: Alpha | H2: =_xlfn.FORECAST.ETS.STAT($B$2:$B$37,$A$2:$A$37,1,1,1) -> 0.501
A3: 44593 | B3: 9.1 | G3: Beta | H3: =_xlfn.FORECAST.ETS.STAT($B$2:$B$37,$A$2:$A$37,2,1,1) -> 0.001
A4: 44621 | B4: 13.272727 | G4: Gamma | H4: =_xlfn.FORECAST.ETS.STAT($B$2:$B$37,$A$2:$A$37,3,1,1) -> 0.001
A5: 44652 | B5: 12.384615 | G5: MASE | H5: =_xlfn.FORECAST.ETS.STAT($B$2:$B$37,$A$2:$A$37,4,1,1) -> 0.065461935
A6: 44682 | B6: 16 | G6: SMAPE | H6: =_xlfn.FORECAST.ETS.STAT($B$2:$B$37,$A$2:$A$37,5,1,1) -> 0.010214808
A7: 44713 | B7: 18.923077 | G7: MAE | H7: =_xlfn.FORECAST.ETS.STAT($B$2:$B$37,$A$2:$A$37,6,1,1) -> 0.15741528
A8: 44743 | B8: 20.307692 | G8: RMSE | H8: =_xlfn.FORECAST.ETS.STAT($B$2:$B$37,$A$2:$A$37,7,1,1) -> 0.18024365
A9: 44774 | B9: 19.166667
A10: 44805 | B10: 16.666667
A11: 44835 | B11: 12.692308
A12: 44866 | B12: 14.454545
A13: 44896 | B13: 14.384615
A14: 44927 | B14: 11.055556
A15: 44958 | B15: 10.1
A16: 44986 | B16: 14.909091
A17: 45017 | B17: 13.692308
A18: 45047 | B18: 17
A19: 45078 | B19: 18.75
A20: 45108 | B20: 21.692308
... A36: 45597 | B36: 14.727273
A37: 45627 | B37: 14.692308 | C37: 14.692308 | D37: 14.692308 | E37: 14.692308
A38: 45658 | C38: =_xlfn.FORECAST.ETS(A38,$B$2:$B$37,$A$2:$A$37,1,1) -> 11.275173 | D38: =C38-_xlfn.FORECAST.ETS.CONFINT(A38,$B$2:$B$37,$A$2:$A$37,0.95,1,1) -> 10.688131 | E38: =C38+_xlfn.FORECAST.ETS.CONFINT(A38,$B$2:$B$37,$A$2:$A$37,0.95,1,1) -> 11.862215
A39: 45689 | C39: =_xlfn.FORECAST.ETS(A39,$B$2:$B$37,$A$2:$A$37,1,1) -> 10.335112 | D39: =C39-_xlfn.FORECAST.ETS.CONFINT(A39,$B$2:$B$37,$A$2:$A$37,0.95,1,1) -> 9.6782537 | E39: =C39+_xlfn.FORECAST.ETS.CONFINT(A39,$B$2:$B$37,$A$2:$A$37,0.95,1,1) -> 10.99197
A40: 45717 | C40: =_xlfn.FORECAST.ETS(A40,$B$2:$B$37,$A$2:$A$37,1,1) -> 15.16909 | D40: =C40-_xlfn.FORECAST.ETS.CONFINT(A40,$B$2:$B$37,$A$2:$A$37,0.95,1,1) -> 14.448913 | E40: =C40+_xlfn.FORECAST.ETS.CONFINT(A40,$B$2:$B$37,$A$2:$A$37,0.95,1,1) -> 15.889266
A41: 45748 | C41: =_xlfn.FORECAST.ETS(A41,$B$2:$B$37,$A$2:$A$37,1,1) -> 13.969141 | D41: =C41-_xlfn.FORECAST.ETS.CONFINT(A41,$B$2:$B$37,$A$2:$A$37,0.95,1,1) -> 13.190557 | E41: =C41+_xlfn.FORECAST.ETS.CONFINT(A41,$B$2:$B$37,$A$2:$A$37,0.95,1,1) -> 14.747724
A42: 45778 | C42: =_xlfn.FORECAST.ETS(A42,$B$2:$B$37,$A$2:$A$37,1,1) -> 17.291351 | D42: =C42-_xlfn.FORECAST.ETS.CONFINT(A42,$B$2:$B$37,$A$2:$A$37,0.95,1,1) -> 16.458237 | E42: =C42+_xlfn.FORECAST.ETS.CONFINT(A42,$B$2:$B$37,$A$2:$A$37,0.95,1,1) -> 18.124465
A43: 45809 | C43: =_xlfn.FORECAST.ETS(A43,$B$2:$B$37,$A$2:$A$37,1,1) -> 19.325357 | D43: =C43-_xlfn.FORECAST.ETS.CONFINT(A43,$B$2:$B$37,$A$2:$A$37,0.95,1,1) -> 18.440872 | E43: =C43+_xlfn.FORECAST.ETS.CONFINT(A43,$B$2:$B$37,$A$2:$A$37,0.95,1,1) -> 20.209841
A44: 45839 | C44: =_xlfn.FORECAST.ETS(A44,$B$2:$B$37,$A$2:$A$37,1,1) -> 21.489096 | D44: =C44-_xlfn.FORECAST.ETS.CONFINT(A44,$B$2:$B$37,$A$2:$A$37,0.95,1,1) -> 20.555877 | E44: =C44+_xlfn.FORECAST.ETS.CONFINT(A44,$B$2:$B$37,$A$2:$A$37,0.95,1,1) -> 22.422314
A45: 45870 | C45: =_xlfn.FORECAST.ETS(A45,$B$2:$B$37,$A$2:$A$37,1,1) -> 19.695611 | D45: =C45-_xlfn.FORECAST.ETS.CONFINT(A45,$B$2:$B$37,$A$2:$A$37,0.95,1,1) -> 18.715902 | E45: =C45+_xlfn.FORECAST.ETS.CONFINT(A45,$B$2:$B$37,$A$2:$A$37,0.95,1,1) -> 20.675321
A46: 45901 | C46: =_xlfn.FORECAST.ETS(A46,$B$2:$B$37,$A$2:$A$37,1,1) -> 17.071462 | D46: =C46-_xlfn.FORECAST.ETS.CONFINT(A46,$B$2:$B$37,$A$2:$A$37,0.95,1,1) -> 16.0472 | E46: =C46+_xlfn.FORECAST.ETS.CONFINT(A46,$B$2:$B$37,$A$2:$A$37,0.95,1,1) -> 18.095725
A47: 45931 | C47: =_xlfn.FORECAST.ETS(A47,$B$2:$B$37,$A$2:$A$37,1,1) -> 13.220349 | D47: =C47-_xlfn.FORECAST.ETS.CONFINT(A47,$B$2:$B$37,$A$2:$A$37,0.95,1,1) -> 12.153227 | E47: =C47+_xlfn.FORECAST.ETS.CONFINT(A47,$B$2:$B$37,$A$2:$A$37,0.95,1,1) -> 14.287471
A48: 45962 | C48: =_xlfn.FORECAST.ETS(A48,$B$2:$B$37,$A$2:$A$37,1,1) -> 15.177888 | D48: =C48-_xlfn.FORECAST.ETS.CONFINT(A48,$B$2:$B$37,$A$2:$A$37,0.95,1,1) -> 14.069404 | E48: =C48+_xlfn.FORECAST.ETS.CONFINT(A48,$B$2:$B$37,$A$2:$A$37,0.95,1,1) -> 16.286372
A49: 45992 | C49: =_xlfn.FORECAST.ETS(A49,$B$2:$B$37,$A$2:$A$37,1,1) -> 14.936194 | D49: =C49-_xlfn.FORECAST.ETS.CONFINT(A49,$B$2:$B$37,$A$2:$A$37,0.95,1,1) -> 13.787684 | E49: =C49+_xlfn.FORECAST.ETS.CONFINT(A49,$B$2:$B$37,$A$2:$A$37,0.95,1,1) -> 16.084705
... A61: 46357 | C61: =_xlfn.FORECAST.ETS(A61,$B$2:$B$37,$A$2:$A$37,1,1) -> 15.246222 | D61: =C61-_xlfn.FORECAST.ETS.CONFINT(A61,$B$2:$B$37,$A$2:$A$37,0.95,1,1) -> 13.686975 | E61: =C61+_xlfn.FORECAST.ETS.CONFINT(A61,$B$2:$B$37,$A$2:$A$37,0.95,1,1) -> 16.80547

Sheet Лист1
A1: sales | B1: Date
A2: 7 | B2: =DATE(sales__2[[#This Row],[year]],sales__2[[#This Row],[month]],1) -> 44562
A3: 8 | B3: =DATE(sales__2[[#This Row],[year]],sales__2[[#This Row],[month]],1) -> 44562
A4: 12 | B4: =DATE(sales__2[[#This Row],[year]],sales__2[[#This Row],[month]],1) -> 44562
A5: 3 | B5: =DATE(sales__2[[#This Row],[year]],sales__2[[#This Row],[month]],1) -> 44562
A6: 18 | B6: =DATE(sales__2[[#This Row],[year]],sales__2[[#This Row],[month]],1) -> 44562
A7: 7 | B7: =DATE(sales__2[[#This Row],[year]],sales__2[[#This Row],[month]],1) -> 44562
A8: 8 | B8: =DATE(sales__2[[#This Row],[year]],sales__2[[#This Row],[month]],1) -> 44562
A9: 15 | B9: =DATE(sales__2[[#This Row],[year]],sales__2[[#This Row],[month]],1) -> 44562
A10: 20 | B10: =DATE(sales__2[[#This Row],[year]],sales__2[[#This Row],[month]],1) -> 44562
A11: 10 | B11: =DATE(sales__2[[#This Row],[year]],sales__2[[#This Row],[month]],1) -> 44562
A12: 6 | B12: =DATE(sales__2[[#This Row],[year]],sales__2[[#This Row],[month]],1) -> 44562
A13: 11 | B13: =DATE(sales__2[[#This Row],[year]],sales__2[[#This Row],[month]],1) -> 44562
... A222: 19 | B222: =DATE(sales__2[[#This Row],[year]],sales__2[[#This Row],[month]],1) -> 45078
A223: 23+H268 | B223: =DATE(sales__2[[#This Row],[year]],sales__2[[#This Row],[month]],1) -> 45078
A224: 12 | B224: =DATE(sales__2[[#This Row],[year]],sales__2[[#This Row],[month]],1) -> 45078
A225: 20 | B225: =DATE(sales__2[[#This Row],[year]],sales__2[[#This Row],[month]],1) -> 45108
A226: 16 | B226: =DATE(sales__2[[#This Row],[year]],sales__2[[#This Row],[month]],1) -> 45108
A227: 16 | B227: =DATE(sales__2[[#This Row],[year]],sales__2[[#This Row],[month]],1) -> 45108
A228: 26 | B228: =DATE(sales__2[[#This Row],[year]],sales__2[[#This Row],[month]],1) -> 45108
A229: 30 | B229: =DATE(sales__2[[#This Row],[year]],sales__2[[#This Row],[month]],1) -> 45108
A230: 30 | B230: =DATE(sales__2[[#This Row],[year]],sales__2[[#This Row],[month]],1) -> 45108
A231: 28 | B231: =DATE(sales__2[[#This Row],[year]],sales__2[[#This Row],[month]],1) -> 45108
A232: 25 | B232: =DATE(sales__2[[#This Row],[year]],sales__2[[#This Row],[month]],1) -> 45108
A233: 19 | B233: =DATE(sales__2[[#This Row],[year]],sales__2[[#This Row],[month]],1) -> 45108
A234: 10 | B234: =DATE(sales__2[[#This Row],[year]],sales__2[[#This Row],[month]],1) -> 45108
A235: 22 | B235: =DATE(sales__2[[#This Row],[year]],sales__2[[#This Row],[month]],1) -> 45108
... A448: 12 | B448: =DATE(sales__2[[#This Row],[year]],sales__2[[#This Row],[month]],1) -> 45627

Sheet Сводная 
A3: Среднее по полю sales | B3: Названия столбцов
A4: Названия строк | B4: 2022 | C4: 2023 | D4: 2024 | E4: Общий итог | F4: Среднее значение | G4: КС
A5: 1 | B5: 12.666667 | C5: 15.666667 | D5: 16.333333 | E5: 14.888889 | F5: =AVERAGE(B5:D5) -> 14.888889 | G5: =F5/F$17 -> 0.7971742
A6: 2 | B6: 11 | C6: 10.5 | D6: 11.5 | E6: 11 | F6: =AVERAGE(B6:D6) -> 11 | G6: =F6/F$17 -> 0.58895706
A7: 3 | B7: 16 | C7: 17.333333 | D7: 17.666667 | E7: 17 | F7: =AVERAGE(B7:D7) -> 17 | G7: =F7/F$17 -> 0.91020636
A8: 4 | B8: 15.5 | C8: 17 | D8: 16.5 | E8: 16.333333 | F8: =AVERAGE(B8:D8) -> 16.333333 | G8: =F8/F$17 -> 0.87451199
A9: 5 | B9: 15.666667 | C9: 17.666667 | D9: 16.666667 | E9: 16.666667 | F9: =AVERAGE(B9:D9) -> 16.666667 | G9: =F9/F$17 -> 0.89235917
A10: 6 | B10: 22 | C10: 22 | D10: 22.333333 | E10: 22.111111 | F10: =AVERAGE(B10:D10) -> 22.111111 | G10: =F10/F$17 -> 1.1838632
A11: 7 | B11: 24.333333 | C11: 26 | D11: 25.333333 | E11: 25.222222 | F11: =AVERAGE(B11:D11) -> 25.222222 | G11: =F11/F$17 -> 1.3504369
A12: 8 | B12: 23 | C12: 24 | D12: 24 | E12: 23.666667 | F12: =AVERAGE(B12:D12) -> 23.666667 | G12: =F12/F$17 -> 1.26715
A13: 9 | B13: 20 | C13: 19.666667 | D13: 19.666667 | E13: 19.777778 | F13: =AVERAGE(B13:D13) -> 19.777778 | G13: =F13/F$17 -> 1.0589329
A14: 10 | B14: 16.5 | C14: 17 | D14: 18 | E14: 17.166667 | F14: =AVERAGE(B14:D14) -> 17.166667 | G14: =F14/F$17 -> 0.91912995
A15: 11 | B15: 16.666667 | C15: 18.666667 | D15: 18 | E15: 17.777778 | F15: =AVERAGE(B15:D15) -> 17.777778 | G15: =F15/F$17 -> 0.95184979
A16: 12 | B16: 18 | C16: 18 | D16: 20 | E16: 18.666667 | F16: =AVERAGE(B16:D16) -> 18.666667 | G16: =F16/F$17 -> 0.99944228
A17: Общий итог | B17: 17.90625 | C17: 19 | D17: 19.125 | E17: 18.677083 | F17: =AVERAGE(B17:D17) -> 18.677083 | G17: =SUM(G5:G16) -> 11.794014

Sheet Ручной прогноз
A1: Дата | B1: Период (t) | C1: Yt (факт) | D1: Lt (сглаж. уровень) | E1: Tt (тренд) | F1: St (сезонность) | G1: Прогноз (Ŷt) | H1: Ошибка | I1: |ошибка|/Yt (факт) | L1: k | M1: 0.80265023 | O1: Названия строк | P1: Сумма по полю sales
A2: 44562 | B2: 1 | C2: =факт!B5 -> 38 | D2: =C2 -> 38 | E2: 0 | F2: =C2/P$2 -> 0.066317627 | G2: =D2 -> 38 | H2: =G2-C2 -> 0 | I2: =ABS(H2)/C2 -> 0 | L2: b | M2: 0.1 | O2: 2022 | P2: 573
A3: 44593 | B3: 2 | C3: =факт!B6 -> 22 | D3: =C3 -> 22 | E3: =$M$2*(D3-D2)+(1-$M$2)*E2 -> -1.6 | F3: =C3/P$2 -> 0.038394415 | G3: =D3 -> 22 | H3: =G3-C3 -> 0 | I3: =ABS(H3)/C3 -> 0 | L3: q | M3: 1 | O3: 2023 | P3: 608
A4: 44621 | B4: 3 | C4: =факт!B7 -> 48 | D4: =C4 -> 48 | E4: =$M$2*(D4-D3)+(1-$M$2)*E3 -> 1.16 | F4: =C4/P$2 -> 0.083769634 | G4: =D4 -> 48 | H4: =G4-C4 -> 0 | I4: =ABS(H4)/C4 -> 0 | L4: s | M4: 12 | O4: 2024 | P4: 612
A5: 44652 | B5: 4 | C5: =факт!B8 -> 31 | D5: =C5 -> 31 | E5: =$M$2*(D5-D4)+(1-$M$2)*E4 -> -0.656 | F5: =C5/P$2 -> 0.054101222 | G5: =D5 -> 31 | H5: =G5-C5 -> 0 | I5: =ABS(H5)/C5 -> 0 | O5: Общий итог | P5: 1793
A6: 44682 | B6: 5 | C6: =факт!B9 -> 47 | D6: =C6 -> 47 | E6: =$M$2*(D6-D5)+(1-$M$2)*E5 -> 1.0096 | F6: =C6/P$2 -> 0.082024433 | G6: =D6 -> 47 | H6: =G6-C6 -> 0 | I6: =ABS(H6)/C6 -> 0 | L6: MAPE | M6: =SUM(I14:I49)/36*100 -> 6.268726
A7: 44713 | B7: 6 | C7: =факт!B10 -> 66 | D7: =C7 -> 66 | E7: =$M$2*(D7-D6)+(1-$M$2)*E6 -> 2.80864 | F7: =C7/P$2 -> 0.11518325 | G7: =D7 -> 66 | H7: =G7-C7 -> 0 | I7: =ABS(H7)/C7 -> 0
A8: 44743 | B8: 7 | C8: =факт!B11 -> 73 | D8: =C8 -> 73 | E8: =$M$2*(D8-D7)+(1-$M$2)*E7 -> 3.227776 | F8: =C8/P$2 -> 0.12739965 | G8: =D8 -> 73 | H8: =G8-C8 -> 0 | I8: =ABS(H8)/C8 -> 0
A9: 44774 | B9: 8 | C9: =факт!B12 -> 69 | D9: =C9 -> 69 | E9: =$M$2*(D9-D8)+(1-$M$2)*E8 -> 2.5049984 | F9: =C9/P$2 -> 0.12041885 | G9: =D9 -> 69 | H9: =G9-C9 -> 0 | I9: =ABS(H9)/C9 -> 0
A10: 44805 | B10: 9 | C10: =факт!B13 -> 60 | D10: =C10 -> 60 | E10: =$M$2*(D10-D9)+(1-$M$2)*E9 -> 1.3544986 | F10: =C10/P$2 -> 0.10471204 | G10: =D10 -> 60 | H10: =G10-C10 -> 0 | I10: =ABS(H10)/C10 -> 0
A11: 44835 | B11: 10 | C11: =факт!B14 -> 33 | D11: =C11 -> 33 | E11: =$M$2*(D11-D10)+(1-$M$2)*E10 -> -1.4809513 | F11: =C11/P$2 -> 0.057591623 | G11: =D11 -> 33 | H11: =G11-C11 -> 0 | I11: =ABS(H11)/C11 -> 0
A12: 44866 | B12: 11 | C12: =факт!B15 -> 50 | D12: =C12 -> 50 | E12: =$M$2*(D12-D11)+(1-$M$2)*E11 -> 0.36714383 | F12: =C12/P$2 -> 0.087260035 | G12: =D12 -> 50 | H12: =G12-C12 -> 0 | I12: =ABS(H12)/C12 -> 0
A13: 44896 | B13: 12 | C13: =факт!B16 -> 36 | D13: =C13 -> 36 | E13: =$M$2*(D13-D12)+(1-$M$2)*E12 -> -1.0695705 | F13: =C13/P$2 -> 0.062827225 | G13: =D13 -> 36 | H13: =G13-C13 -> 0 | I13: =ABS(H13)/C13 -> 0
A14: 44927 | B14: 13 | C14: =факт!B18 -> 47 | D14: =$M$1*C14/F2+(1-$M$1)*(D13+E13) -> 575.74018 | E14: =$M$2*(D14-D13)+(1-$M$2)*E13 -> 53.011405 | F14: =$M$3*(C14/D14)+(1-$M$3)*F2 -> 0.081634045 | G14: =(D13+E13)*F2 -> 2.3165032 | H14: =G14-C14 -> -44.683497 | I14: =ABS(H14)/C14 -> 0.9507127
A15: 44958 | B15: 14 | C15: =факт!B19 -> 21 | D15: =$M$1*C15/F3+(1-$M$1)*(D14+E14) -> 563.09717 | E15: =$M$2*(D15-D14)+(1-$M$2)*E14 -> 46.445963 | F15: =$M$3*(C15/D15)+(1-$M$3)*F3 -> 0.037293741 | G15: =(D14+E14)*F3 -> 24.14055 | H15: =G15-C15 -> 3.1405495 | I15: =ABS(H15)/C15 -> 0.14954998
A16: 44986 | B16: 15 | C16: =факт!B20 -> 52 | D16: =$M$1*C16/F4+(1-$M$1)*(D15+E15) -> 618.53833 | E16: =$M$2*(D16-D15)+(1-$M$2)*E15 -> 47.345483 | F16: =$M$3*(C16/D16)+(1-$M$3)*F4 -> 0.084069164 | G16: =(D15+E15)*F4 -> 51.061205 | H16: =G16-C16 -> -0.93879493 | I16: =ABS(H16)/C16 -> 0.018053749
A17: 45017 | B17: 16 | C17: =факт!B21 -> 34 | D17: =$M$1*C17/F5+(1-$M$1)*(D16+E16) -> 635.83885 | E17: =$M$2*(D17-D16)+(1-$M$2)*E16 -> 44.340986 | F17: =$M$3*(C17/D17)+(1-$M$3)*F5 -> 0.053472669 | G17: =(D16+E16)*F5 -> 36.025128 | H17: =G17-C17 -> 2.0251276 | I17: =ABS(H17)/C17 -> 0.059562577
A18: 45047 | B18: 17 | C18: =факт!B22 -> 53 | D18: =$M$1*C18/F6+(1-$M$1)*(D17+E17) -> 652.86493 | E18: =$M$2*(D18-D17)+(1-$M$2)*E17 -> 41.609495 | F18: =$M$3*(C18/D18)+(1-$M$3)*F6 -> 0.081180651 | G18: =(D17+E17)*F6 -> 55.791365 | H18: =G18-C18 -> 2.7913651 | I18: =ABS(H18)/C18 -> 0.052667267
A19: 45078 | B19: 18 | C19: =факт!B23 -> 66 | D19: =$M$1*C19/F7+(1-$M$1)*(D18+E18) -> 596.97295 | E19: =$M$2*(D19-D18)+(1-$M$2)*E18 -> 31.859348 | F19: =$M$3*(C19/D19)+(1-$M$3)*F7 -> 0.11055777 | G19: =(D18+E18)*F7 -> 79.991818 | H19: =G19-C19 -> 13.991818 | I19: =ABS(H19)/C19 -> 0.21199725
A20: 45108 | B20: 19 | C20: =факт!B24 -> 78 | D20: =$M$1*C20/F8+(1-$M$1)*(D19+E19) -> 615.51976 | E20: =$M$2*(D20-D19)+(1-$M$2)*E19 -> 30.528095 | F20: =$M$3*(C20/D20)+(1-$M$3)*F8 -> 0.12672217 | G20: =(D19+E19)*F8 -> 80.113015 | H20: =G20-C20 -> 2.1130152 | I20: =ABS(H20)/C20 -> 0.027089938
A21: 45139 | B21: 20 | C21: =факт!B25 -> 72 | D21: =$M$1*C21/F9+(1-$M$1)*(D20+E20) -> 607.41244 | E21: =$M$2*(D21-D20)+(1-$M$2)*E20 -> 26.664553 | F21: =$M$3*(C21/D21)+(1-$M$3)*F9 -> 0.1185356 | G21: =(D20+E20)*F9 -> 77.796339 | H21: =G21-C21 -> 5.796339 | I21: =ABS(H21)/C21 -> 0.080504708
A22: 45170 | B22: 21 | C22: =факт!B26 -> 59 | D22: =$M$1*C22/F10+(1-$M$1)*(D21+E21) -> 577.38822 | E22: =$M$2*(D22-D21)+(1-$M$2)*E21 -> 20.995676 | F22: =$M$3*(C22/D22)+(1-$M$3)*F10 -> 0.10218428 | G22: =(D21+E21)*F10 -> 66.395496 | H22: =G22-C22 -> 7.3954964 | I22: =ABS(H22)/C22 -> 0.1253474
A23: 45200 | B23: 22 | C23: =факт!B27 -> 34 | D23: =$M$1*C23/F11+(1-$M$1)*(D22+E22) -> 591.94643 | E23: =$M$2*(D23-D22)+(1-$M$2)*E22 -> 20.351929 | F23: =$M$3*(C23/D23)+(1-$M$3)*F11 -> 0.05743763 | G23: =(D22+E22)*F11 -> 34.4619 | H23: =G23-C23 -> 0.46189977 | I23: =ABS(H23)/C23 -> 0.013585287
A24: 45231 | B24: 23 | C24: =факт!B28 -> 56 | D24: =$M$1*C24/F12+(1-$M$1)*(D23+E23) -> 635.94575 | E24: =$M$2*(D24-D23)+(1-$M$2)*E23 -> 22.716668 | F24: =$M$3*(C24/D24)+(1-$M$3)*F12 -> 0.088057825 | G24: =(D23+E23)*F12 -> 53.429176 | H24: =G24-C24 -> -2.5708235 | I24: =ABS(H24)/C24 -> 0.045907563
A25: 45261 | B25: 24 | C25: =факт!B29 -> 36 | D25: =$M$1*C25/F13+(1-$M$1)*(D24+E24) -> 589.90546 | E25: =$M$2*(D25-D24)+(1-$M$2)*E24 -> 15.840972 | F25: =$M$3*(C25/D25)+(1-$M$3)*F13 -> 0.061026728 | G25: =(D24+E24)*F13 -> 41.381932 | H25: =G25-C25 -> 5.3819322 | I25: =ABS(H25)/C25 -> 0.14949812
A26: 45292 | B26: 25 | C26: =факт!B31 -> 49 | D26: =$M$1*C26/F14+(1-$M$1)*(D25+E25) -> 601.3265 | E26: =$M$2*(D26-D25)+(1-$M$2)*E25 -> 15.398979 | F26: =$M$3*(C26/D26)+(1-$M$3)*F14 -> 0.081486513 | G26: =(D25+E25)*F14 -> 49.449532 | H26: =G26-C26 -> 0.4495316 | I26: =ABS(H26)/C26 -> 0.0091741143
A27: 45323 | B27: 26 | C27: =факт!B32 -> 23 | D27: =$M$1*C27/F15+(1-$M$1)*(D26+E26) -> 616.72548 | E27: =$M$2*(D27-D26)+(1-$M$2)*E26 -> 15.398979 | F27: =$M$3*(C27/D27)+(1-$M$3)*F15 -> 0.037293741 | G27: =(D26+E26)*F15 -> 23 | H27: =G27-C27 -> 2.8394287e-07 | I27: =ABS(H27)/C27 -> 1.2345342e-08
A28: 45352 | B28: 27 | C28: =факт!B33 -> 53 | D28: =$M$1*C28/F16+(1-$M$1)*(D27+E27) -> 630.76705 | E28: =$M$2*(D28-D27)+(1-$M$2)*E27 -> 15.263238 | F28: =$M$3*(C28/D28)+(1-$M$3)*F16 -> 0.084024681 | G28: =(D27+E27)*F16 -> 53.142174 | H28: =G28-C28 -> 0.14217432 | I28: =ABS(H28)/C28 -> 0.0026825343
A29: 45383 | B29: 28 | C29: =факт!B34 -> 33 | D29: =$M$1*C29/F17+(1-$M$1)*(D28+E28) -> 622.83965 | E29: =$M$2*(D29-D28)+(1-$M$2)*E28 -> 12.944174 | F29: =$M$3*(C29/D29)+(1-$M$3)*F17 -> 0.052983139 | G29: =(D28+E28)*F17 -> 34.544963 | H29: =G29-C29 -> 1.5449632 | I29: =ABS(H29)/C29 -> 0.046817068
A30: 45413 | B30: 29 | C30: =факт!B35 -> 50 | D30: =$M$1*C30/F18+(1-$M$1)*(D29+E29) -> 619.83234 | E30: =$M$2*(D30-D29)+(1-$M$2)*E29 -> 11.349026 | F30: =$M$3*(C30/D30)+(1-$M$3)*F18 -> 0.080666975 | G30: =(D29+E29)*F18 -> 51.613345 | H30: =G30-C30 -> 1.613345 | I30: =ABS(H30)/C30 -> 0.0322669
A31: 45444 | B31: 30 | C31: =факт!B36 -> 67 | D31: =$M$1*C31/F19+(1-$M$1)*(D30+E30) -> 610.98398 | E31: =$M$2*(D31-D30)+(1-$M$2)*E30 -> 9.3292874 | F31: =$M$3*(C31/D31)+(1-$M$3)*F19 -> 0.10965918 | G31: =(D30+E30)*F19 -> 69.782007 | H31: =G31-C31 -> 2.7820066 | I31: =ABS(H31)/C31 -> 0.041522487
A32: 45474 | B32: 31 | C32: =факт!B37 -> 76 | D32: =$M$1*C32/F20+(1-$M$1)*(D31+E31) -> 603.79789 | E32: =$M$2*(D32-D31)+(1-$M$2)*E31 -> 7.6777494 | F32: =$M$3*(C32/D32)+(1-$M$3)*F20 -> 0.12586993 | G32: =(D31+E31)*F20 -> 78.607443 | H32: =G32-C32 -> 2.6074431 | I32: =ABS(H32)/C32 -> 0.034308462
A33: 45505 | B33: 32 | C33: =факт!B38 -> 72 | D33: =$M$1*C33/F21+(1-$M$1)*(D32+E32) -> 608.21431 | E33: =$M$2*(D33-D32)+(1-$M$2)*E32 -> 7.3516167 | F33: =$M$3*(C33/D33)+(1-$M$3)*F21 -> 0.11837933 | G33: =(D32+E32)*F21 -> 72.481634 | H33: =G33-C33 -> 0.48163361 | I33: =ABS(H33)/C33 -> 0.0066893557
A34: 45536 | B34: 33 | C34: =факт!B39 -> 59 | D34: =$M$1*C34/F22+(1-$M$1)*(D33+E33) -> 584.92258 | E34: =$M$2*(D34-D33)+(1-$M$2)*E33 -> 4.2872823 | F34: =$M$3*(C34/D34)+(1-$M$3)*F22 -> 0.10086805 | G34: =(D33+E33)*F22 -> 62.901161 | H34: =G34-C34 -> 3.9011614 | I34: =ABS(H34)/C34 -> 0.06612138
A35: 45566 | B35: 34 | C35: =факт!B40 -> 36 | D35: =$M$1*C35/F23+(1-$M$1)*(D34+E34) -> 619.35496 | E35: =$M$2*(D35-D34)+(1-$M$2)*E34 -> 7.3017915 | F35: =$M$3*(C35/D35)+(1-$M$3)*F23 -> 0.058124989 | G35: =(D34+E34)*F23 -> 33.842818 | H35: =G35-C35 -> -2.157182 | I35: =ABS(H35)/C35 -> 0.059921723
A36: 45597 | B36: 35 | C36: =факт!B41 -> 54 | D36: =$M$1*C36/F24+(1-$M$1)*(D35+E35) -> 615.8825 | E36: =$M$2*(D36-D35)+(1-$M$2)*E35 -> 6.2243665 | F36: =$M$3*(C36/D36)+(1-$M$3)*F24 -> 0.087679062 | G36: =(D35+E35)*F24 -> 55.18203 | H36: =G36-C36 -> 1.1820304 | I36: =ABS(H36)/C36 -> 0.021889453
A37: 45627 | B37: 36 | C37: =факт!B42 -> 40 | D37: =$M$1*C37/F25+(1-$M$1)*(D36+E36) -> 648.87015 | E37: =$M$2*(D37-D36)+(1-$M$2)*E36 -> 8.900695 | F37: =$M$3*(C37/D37)+(1-$M$3)*F25 -> 0.061645616 | G37: =(D36+E36)*F25 -> 37.965146 | H37: =G37-C37 -> -2.0348536 | I37: =ABS(H37)/C37 -> 0.050871339
A38: 45658 | D38: =$M$1*C37/F26+(1-$M$1)*(D37+E37) -> 523.81489 | E38: =$M$2*(D38-D37)+(1-$M$2)*E37 -> -4.4949006 | F38: =$M$3*(C26/D38)+(1-$M$3)*F26 -> 0.093544497 | G38: =(D37+E37)*F26 -> 53.599453
A39: 45689 | D39: =$M$1*G27/F27+(1-$M$1)*(D38+E38) -> 597.50253 | E39: =$M$2*(D39-D38)+(1-$M$2)*E38 -> 3.3233538 | F39: =$M$3*(C27/D39)+(1-$M$3)*F27 -> 0.038493561 | G39: =(D38+E38)*F27 -> 19.367385
A40: 45717 | D40: =$M$1*G28/F28+(1-$M$1)*(D39+E39) -> 626.21629 | E40: =$M$2*(D40-D39)+(1-$M$2)*E39 -> 5.8623945 | F40: =$M$3*(C28/D40)+(1-$M$3)*F28 -> 0.084635294 | G40: =(D39+E39)*F28 -> 50.484204
...

Sheet Ошибка
A1: фактические значения | B1: Прогноз | C1: абсолютная ошибка | D1: относительная ошибка
A2: ='Ручной прогноз'!C26 -> 49 | B2: ='Ручной прогноз'!G26 -> 49.449532 | C2: =ABS(A2-B2) -> 0.4495316 | D2: =C2/A2 -> 0.0091741143
A3: ='Ручной прогноз'!C27 -> 23 | B3: ='Ручной прогноз'!G27 -> 23 | C3: =ABS(A3-B3) -> 2.8394287e-07 | D3: =C3/A3 -> 1.2345342e-08
A4: ='Ручной прогноз'!C28 -> 53 | B4: ='Ручной прогноз'!G28 -> 53.142174 | C4: =ABS(A4-B4) -> 0.14217432 | D4: =C4/A4 -> 0.0026825343
A5: ='Ручной прогноз'!C29 -> 33 | B5: ='Ручной прогноз'!G29 -> 34.544963 | C5: =ABS(A5-B5) -> 1.5449632 | D5: =C5/A5 -> 0.046817068
A6: ='Ручной прогноз'!C30 -> 50 | B6: ='Ручной прогноз'!G30 -> 51.613345 | C6: =ABS(A6-B6) -> 1.613345 | D6: =C6/A6 -> 0.0322669
A7: ='Ручной прогноз'!C31 -> 67 | B7: ='Ручной прогноз'!G31 -> 69.782007 | C7: =ABS(A7-B7) -> 2.7820066 | D7: =C7/A7 -> 0.041522487
A8: ='Ручной прогноз'!C32 -> 76 | B8: ='Ручной прогноз'!G32 -> 78.607443 | C8: =ABS(A8-B8) -> 2.6074431 | D8: =C8/A8 -> 0.034308462
A9: ='Ручной прогноз'!C33 -> 72 | B9: ='Ручной прогноз'!G33 -> 72.481634 | C9: =ABS(A9-B9) -> 0.48163361 | D9: =C9/A9 -> 0.0066893557
A10: ='Ручной прогноз'!C34 -> 59 | B10: ='Ручной прогноз'!G34 -> 62.901161 | C10: =ABS(A10-B10) -> 3.9011614 | D10: =C10/A10 -> 0.06612138
A11: ='Ручной прогноз'!C35 -> 36 | B11: ='Ручной прогноз'!G35 -> 33.842818 | C11: =ABS(A11-B11) -> 2.157182 | D11: =C11/A11 -> 0.059921723
A12: ='Ручной прогноз'!C36 -> 54 | B12: ='Ручной прогноз'!G36 -> 55.18203 | C12: =ABS(A12-B12) -> 1.1820304 | D12: =C12/A12 -> 0.021889453
A13: ='Ручной прогноз'!C37 -> 40 | B13: ='Ручной прогноз'!G37 -> 37.965146 | C13: =ABS(A13-B13) -> 2.0348536 | D13: =C13/A13 -> 0.050871339
C14: MAPE | D14: MSE
C15: =SUMSQ(C2:C13)/12 -> 3.7827247 | D15: =SUM(D2:D13)/12*100 -> 3.1022069
